Workbook
Name Cat2AList: Lookup!$A$22:$A$32
Name Cat2BList: Lookup!$D$22:$D$33
Name Cat2CList: Lookup!$G$22:$G$33
Name Cat3AAuthorList: Lookup!$M$2:$M$4
Name Cat3AClassList: Lookup!$L$2:$L$7
Name Cat3BCategoryList: Lookup!$N$2:$N$12
Name CourseIn: Lookup!$J$2:$J$3
Name ExamMode: Lookup!$K$2:$K$5

Sheet Dashboard
A1: Internal Promotion Policy | B1: Eligibility for Post
A2: IPS-2017 | B2: Assitant Professor Level 11
A3: IPS-2022 | B3: Assitant Professor Level 12
B4: Assitant Professor Level 13A
B5: Assitant Professor Level 13B
B6: Assitant Professor Level 14A
A8: Category 1
A9: API 1.A | B9: API 1.B | C9: API 1.C | D9: Final API Score (Category 1)
A12: Category 2
A13: API 2.A | B13: API 2.B | C13: API 2.C | D13: Final API Score (Category 2)
A16: Category 3
A17: API 2.A | B17: API 2.B | C17: API 2.C | D17: Final API Score (Category 2)
A21: Ceiling | B21: API-1.A | C21: API-1.B | D21: API-1.C | E21: API-2.A | F21: API-2.B | G21: API-2.C | H21: API-3.A | I21: API-3.B
A22: IPS-2017 | B22: 60 | C22: 20 | D22: 15 | E22: 15 | F22: 15 | G22: 15 | H22: NA | I22: NA
A23: IPS-2022

Sheet Lookup
J1: CourseIn | K1: ExamMode | L1: Cat3A Classification List | M1: Cat3A Author List | N1: Cat3B Category List
A2: Minimum Threshold | J2: Post Graduate | K2: Examination Duty | L2: Papers in ABDC with A or A* | M2: Single Author | N2: Award and Fellowship
A3: IPS-2017 | B3: Categoy 1/Year | C3: Category 2/Last 4 Years | D3: Category 3/Last 4 Years | E3: (Category 2 + Category 3) / Last 4 Years | J3: Under Graduate | K3: Viva | L3: ABDC with B | M3: First or Corresponding Author/Supervisor/Mentor | N3: Invited Lecture
A4: Assistant Professor Level 12 | B4: 80 | C4: 70 | D4: 70 | E4: 160 | K4: Evaluation | L4: ABDC with C / Scopus / UGC | M4: Co-Author | N4: Papers Presented in Conferences/Seminars/Workshops
A5: Assistant Professor Level 13A | B5: 75 | C5: 70 | D5: 100 | E5: 190 | K5: Invigilation | L5: Any other / Impact Factor less than 1 | N5: Chapters in Books
A6: Associate Professor Level 13B | B6: 70 | C6: 70 | D6: 120 | E6: 220 | L6: Papers published in Refereed Journal (Without Impact Factor) | N6: Subject Books Published by National level Publisher/State with ISBN/ISSN Number
A7: Professor Level 14A | B7: 70 | C7: 70 | D7: 140 | E7: 230 | L7: Paper in Other Reputed Journal (Non-Refereed Journal) | N7: Subject Books published by Other local publishers, with ISBN/ISSN number
A8: IPS-2020 | B8: Categoy 1/Year | C8: Category 2/Last 4 Years | D8: Category 3/Last 4 Years | E8: (Category 2 + Category 3) / Last 4 Years | N8: Text/Reference Books published by an International Publisher with ISBN/ISSN number
A9: Assistant Professor Level 12 | N9: Research Guidance
A10: Assistant Professor Level 13A | N10: Consultancy Projects
A11: Associate Professor Level 13B | N11: Project Outcomes / Outputs
A12: Professor Level 14A | N12: Sponsored Research Projects
A14: Assumptions
A15: Academic Year Duration | B15: 1 July-30 June
A16: Average Feedback per Course | B16: 3.5
A18: Category 2 Tables
A21: Type | B21: Score | D21: Type | E21: Score | G21: Type | H21: Score
A22: NSS/NCC | B22: 100 | D22: Dean/Chairperson/Admission Committee Chairman | E22: 60 | G22: Seminar / Workshop / Symposia | H22: 20
A23: Counselling | B23: 50 | D23: Programme Director/Incharge (Certificate Programme) | E23: 45 | G23: Conferences | H23: 20
A24: Sports | B24: 20 | D24: Programme Director (Full-Time)/Part-Time/Executive | E24: 30 | G24: Faculty Development Course | H24: 20
A25: Exhibition | B25: 20 | D25: PD for MDP of 1-3 days | E25: 10 | G25: Short Term Training Courses | H25: 20
A26: Competition | B26: 20 | D26: PD for MDP of 3-7 days | E26: 12.5 | G26: Membership of Association (National Level) | H26: 30
A27: Departmental Cultural Activities | B27: 20 | D27: Examination Cell In-charge/Controller of Examination/Admission Committee Member | E27: 45 | G27: Membership of Association (State Level) | H27: 20
A28: NGO | B28: 100 | D28: Committee Member/Warden | E28: 15 | G28: General Article Publications | H28: 20
A29: Institutional Cultural Activities | B29: 50 | D29: Asst. Warden | E29: 7.5 | G29: General Awareness Activity | H29: 20
A30: Port Visit | B30: 200 | D30: Board Member | E30: 30 | G30: Community work | H30: 10
A31: Study Tour | B31: 20 | D31: GD/PI/VIVA | E31: 2 | G31: Editorial | H31: 100
A32: Workshop | B32: 50 | D32: Academic Council Coordinator | E32: 15 | G32: Committee Member | H32: 50
D33: BoM Member | E33: 15 | G33: Committee Chair | H33: 100
A36: Category 3 Tables
A39: Classification | B39: AuthorType | C39: Score | E39: Category | F39: Type | G39: Score
A40: Papers in ABDC with A or A* | B40: Single Author | C40: 45 | E40: Award and Fellowship | F40: International Award / Fellowship from Academic Bodies/Associations | G40: 15
A41: Papers in ABDC with A or A* | B41: First or Corresponding Author/Supervisor/Mentor | C41: 31.5 | E41: Award and Fellowship | F41: National Award / Fellowship from Academic Bodies/Associations | G41: 10
A42: Papers in ABDC with A or A* | B42: Co-Author | C42: 13.5 | E42: Award and Fellowship | F42: State / University Award/Fellowship from Academic Bodies/Associations | G42: 5
A43: ABDC with B | B43: Single Author | C43: 40 | E43: Invited Lecture | F43: International | G43: 7
A44: ABDC with B | B44: First or Corresponding Author/Supervisor/Mentor | C44: 28 | E44: Invited Lecture | F44: National | G44: 5
A45: ABDC with B | B45: Co-Author | C45: 12 | E45: Invited Lecture | F45: Regional/State/Local | G45: 3
A46: ABDC with C / Scopus / UGC | B46: Single Author | C46: 35 | E46: Papers Presented in Conferences/Seminars/Workshops | F46: International | G46: 5
A47: ABDC with C / Scopus / UGC | B47: First or Corresponding Author/Supervisor/Mentor | C47: 24.5 | E47: Papers Presented in Conferences/Seminars/Workshops | F47: National | G47: 3
A48: ABDC with C / Scopus / UGC | B48: Co-Author | C48: 10.5 | E48: Papers Presented in Conferences/Seminars/Workshops | F48: Regional/State | G48: 2
...

Sheet API 2025-26
A1: Category 1
A2: A | B2: Direct Teaching
B4: S. No. | C4: Course Name | D4: Course in | E4: Course Hours | F4: Total Course Hours | G4: API Score | H4: AY | J4: Max: | K4: =60 -> 60
B5: 1 | F5: =IF(OR(C5="",D5="",E5=""),"",IF(D5="Post Graduate",ROUND(E5*7/3,0),IF(D5="Under Graduate",ROUND(ROUND(E5*7/3,0)/2,1),""))) | G5: =IF(F5="","",ROUND(F5/10,2)) | H5: ="2025-26" -> 2025-26
B6: 2 | F6: =IF(OR(C6="",D6="",E6=""),"",IF(D6="Post Graduate",ROUND(E6*7/3,0),IF(D6="Under Graduate",ROUND(ROUND(E6*7/3,0)/2,1),""))) | G6: =IF(F6="","",ROUND(F6/10,2)) | H6: ="2025-26" -> 2025-26
B7: 3 | F7: =IF(OR(C7="",D7="",E7=""),"",IF(D7="Post Graduate",ROUND(E7*7/3,0),IF(D7="Under Graduate",ROUND(ROUND(E7*7/3,0)/2,1),""))) | G7: =IF(F7="","",ROUND(F7/10,2)) | H7: ="2025-26" -> 2025-26
B8: 4 | F8: =IF(OR(C8="",D8="",E8=""),"",IF(D8="Post Graduate",ROUND(E8*7/3,0),IF(D8="Under Graduate",ROUND(ROUND(E8*7/3,0)/2,1),""))) | G8: =IF(F8="","",ROUND(F8/10,2)) | H8: ="2025-26" -> 2025-26
B9: 5 | F9: =IF(OR(C9="",D9="",E9=""),"",IF(D9="Post Graduate",ROUND(E9*7/3,0),IF(D9="Under Graduate",ROUND(ROUND(E9*7/3,0)/2,1),""))) | G9: =IF(F9="","",ROUND(F9/10,2)) | H9: ="2025-26" -> 2025-26
D10: Total Hours | E10: =SUM(E5:E9) -> 0 | F10: =SUM(F5:F9) -> 0 | G10: =SUM(G5:G9) -> 0 | H10: Final API 1.A
D11: API 1.A | E11: =G10 -> 0 | H11: =MIN(E11,K4) -> 0
A13: B | B13: Examination Duties/Invigilation/Question Paper Setting / Evaluation
B15: S. No. | C15: Course | D15: Activity | E15: Hours | F15: Score | G15: AY | J15: Max: | K15: =20 -> 20
B16: Score/Point for Question Paper Setting | D16: (No. of courses taught) X 10 | E16: =COUNTA(C5:C9)*10 -> 0 | F16: =ROUND(E16/10,2) -> 0 | G16: ="2025-26" -> 2025-26
B17: Score/Point for Answer script Evalutation | D17: (No. of courses taught) X 20 | E17: =COUNTA(C5:C9)*20 -> 0 | F17: =ROUND(E17/10,2) -> 0 | G17: ="2025-26" -> 2025-26
B18: 1 | F18: =IF(OR(D18="",E18=""),"",ROUND(E18/10,2)) | G18: ="2025-26" -> 2025-26
B19: 2 | F19: =IF(OR(D19="",E19=""),"",ROUND(E19/10,2)) | G19: ="2025-26" -> 2025-26
B20: 3 | F20: =IF(OR(D20="",E20=""),"",ROUND(E20/10,2)) | G20: ="2025-26" -> 2025-26
B21: 4 | F21: =IF(OR(D21="",E21=""),"",ROUND(E21/10,2)) | G21: ="2025-26" -> 2025-26
B22: 5 | F22: =IF(OR(D22="",E22=""),"",ROUND(E22/10,2)) | G22: ="2025-26" -> 2025-26
B23: 6 | F23: =IF(OR(D23="",E23=""),"",ROUND(E23/10,2)) | G23: ="2025-26" -> 2025-26
B24: 7 | F24: =IF(OR(D24="",E24=""),"",ROUND(E24/10,2)) | G24: ="2025-26" -> 2025-26
B25: 8 | F25: =IF(OR(D25="",E25=""),"",ROUND(E25/10,2)) | G25: ="2025-26" -> 2025-26
B26: 9 | F26: =IF(OR(D26="",E26=""),"",ROUND(E26/10,2)) | G26: ="2025-26" -> 2025-26
B27: 10 | F27: =IF(OR(D27="",E27=""),"",ROUND(E27/10,2)) | G27: ="2025-26" -> 2025-26
B28: 11 | F28: =IF(OR(D28="",E28=""),"",ROUND(E28/10,2)) | G28: ="2025-26" -> 2025-26
B29: 12 | F29: =IF(OR(D29="",E29=""),"",ROUND(E29/10,2)) | G29: ="2025-26" -> 2025-26
D30: Total | E30: =SUM(E16:E29) -> 0 | F30: =SUM(F16:F29) -> 0 | G30: Final API 1.B
D31: API 1.B | E31: =F30 -> 0 | G31: =MIN(E31,K15) -> 0
A33: C | B33: Innovative Teaching
B35: S. No. | C35: Course Name | D35: Course in | E35: Course Hours | F35: Innovative Teaching Hours | G35: AY | J35: Max: | K35: =15 -> 15
B36: 1 | C36: =IF(C5="","",C5) | D36: =IF(D5="","",D5) | E36: =IF(E5="","",E5) | F36: =IF(E36="","",ROUND(E36/3,2)) | G36: ="2025-26" -> 2025-26
B37: 2 | C37: =IF(C6="","",C6) | D37: =IF(D6="","",D6) | E37: =IF(E6="","",E6) | F37: =IF(E37="","",ROUND(E37/3,2)) | G37: ="2025-26" -> 2025-26
B38: 3 | C38: =IF(C7="","",C7) | D38: =IF(D7="","",D7) | E38: =IF(E7="","",E7) | F38: =IF(E38="","",ROUND(E38/3,2)) | G38: ="2025-26" -> 2025-26
B39: 4 | C39: =IF(C8="","",C8) | D39: =IF(D8="","",D8) | E39: =IF(E8="","",E8) | F39: =IF(E39="","",ROUND(E39/3,2)) | G39: ="2025-26" -> 2025-26
B40: 5 | C40: =IF(C9="","",C9) | D40: =IF(D9="","",D9) | E40: =IF(E9="","",E9) | F40: =IF(E40="","",ROUND(E40/3,2)) | G40: ="2025-26" -> 2025-26
E41: Total Hours | F41: =SUM(F36:F40) -> 0 | G41: Final API 1.C
E42: API-1.A | F42: =ROUND(F41/10,2) -> 0 | G42: =MIN(F42,K35) -> 0
B44: API-1.A | C44: API-1.B | D44: API-1.C | E44: Final Score (Category 1)
B45: =H11 -> 0 | C45: =G31 -> 0 | D45: =G42 -> 0 | E45: =SUM(B45:D45) -> 0
A47: Category 2
...

Sheet 2026-27
A1: Category 1
A2: A | B2: Direct Teaching
B4: S. No. | C4: Course Name | D4: Course in | E4: Course Hours | F4: Total Course Hours | G4: API Score | H4: AY | J4: Max: | K4: =60 -> 60
B5: 1 | F5: =IF(OR(C5="",D5="",E5=""),"",IF(D5="Post Graduate",ROUND(E5*7/3,0),IF(D5="Under Graduate",ROUND(ROUND(E5*7/3,0)/2,1),""))) | G5: =IF(F5="","",ROUND(F5/10,2)) | H5: ="2026-27" -> 2026-27
B6: 2 | F6: =IF(OR(C6="",D6="",E6=""),"",IF(D6="Post Graduate",ROUND(E6*7/3,0),IF(D6="Under Graduate",ROUND(ROUND(E6*7/3,0)/2,1),""))) | G6: =IF(F6="","",ROUND(F6/10,2)) | H6: ="2026-27" -> 2026-27
B7: 3 | F7: =IF(OR(C7="",D7="",E7=""),"",IF(D7="Post Graduate",ROUND(E7*7/3,0),IF(D7="Under Graduate",ROUND(ROUND(E7*7/3,0)/2,1),""))) | G7: =IF(F7="","",ROUND(F7/10,2)) | H7: ="2026-27" -> 2026-27
B8: 4 | F8: =IF(OR(C8="",D8="",E8=""),"",IF(D8="Post Graduate",ROUND(E8*7/3,0),IF(D8="Under Graduate",ROUND(ROUND(E8*7/3,0)/2,1),""))) | G8: =IF(F8="","",ROUND(F8/10,2)) | H8: ="2026-27" -> 2026-27
B9: 5 | F9: =IF(OR(C9="",D9="",E9=""),"",IF(D9="Post Graduate",ROUND(E9*7/3,0),IF(D9="Under Graduate",ROUND(ROUND(E9*7/3,0)/2,1),""))) | G9: =IF(F9="","",ROUND(F9/10,2)) | H9: ="2026-27" -> 2026-27
D10: Total Hours | E10: =SUM(E5:E9) -> 0 | F10: =SUM(F5:F9) -> 0 | G10: =SUM(G5:G9) -> 0 | H10: Final API 1.A
D11: API 1.A | E11: =G10 -> 0 | H11: =MIN(E11,K4) -> 0
A13: B | B13: Examination Duties/Invigilation/Question Paper Setting / Evaluation
B15: S. No. | C15: Course | D15: Activity | E15: Hours | F15: Score | G15: AY | J15: Max: | K15: =20 -> 20
B16: Score/Point for Question Paper Setting | D16: (No. of courses taught) X 10 | E16: =COUNTA(C5:C9)*10 -> 0 | F16: =ROUND(E16/10,2) -> 0 | G16: ="2026-27" -> 2026-27
B17: Score/Point for Answer script Evalutation | D17: (No. of courses taught) X 20 | E17: =COUNTA(C5:C9)*20 -> 0 | F17: =ROUND(E17/10,2) -> 0 | G17: ="2026-27" -> 2026-27
B18: 1 | F18: =IF(OR(D18="",E18=""),"",ROUND(E18/10,2)) | G18: ="2026-27" -> 2026-27
B19: 2 | F19: =IF(OR(D19="",E19=""),"",ROUND(E19/10,2)) | G19: ="2026-27" -> 2026-27
B20: 3 | F20: =IF(OR(D20="",E20=""),"",ROUND(E20/10,2)) | G20: ="2026-27" -> 2026-27
B21: 4 | F21: =IF(OR(D21="",E21=""),"",ROUND(E21/10,2)) | G21: ="2026-27" -> 2026-27
B22: 5 | F22: =IF(OR(D22="",E22=""),"",ROUND(E22/10,2)) | G22: ="2026-27" -> 2026-27
B23: 6 | F23: =IF(OR(D23="",E23=""),"",ROUND(E23/10,2)) | G23: ="2026-27" -> 2026-27
B24: 7 | F24: =IF(OR(D24="",E24=""),"",ROUND(E24/10,2)) | G24: ="2026-27" -> 2026-27
B25: 8 | F25: =IF(OR(D25="",E25=""),"",ROUND(E25/10,2)) | G25: ="2026-27" -> 2026-27
B26: 9 | F26: =IF(OR(D26="",E26=""),"",ROUND(E26/10,2)) | G26: ="2026-27" -> 2026-27
B27: 10 | F27: =IF(OR(D27="",E27=""),"",ROUND(E27/10,2)) | G27: ="2026-27" -> 2026-27
B28: 11 | F28: =IF(OR(D28="",E28=""),"",ROUND(E28/10,2)) | G28: ="2026-27" -> 2026-27
B29: 12 | F29: =IF(OR(D29="",E29=""),"",ROUND(E29/10,2)) | G29: ="2026-27" -> 2026-27
D30: Total | E30: =SUM(E16:E29) -> 0 | F30: =SUM(F16:F29) -> 0 | G30: Final API 1.B
D31: API 1.B | E31: =F30 -> 0 | G31: =MIN(E31,K15) -> 0
A33: C | B33: Innovative Teaching
B35: S. No. | C35: Course Name | D35: Course in | E35: Course Hours | F35: Innovative Teaching Hours | G35: AY | J35: Max: | K35: =15 -> 15
B36: 1 | C36: =IF(C5="","",C5) | D36: =IF(D5="","",D5) | E36: =IF(E5="","",E5) | F36: =IF(E36="","",ROUND(E36/3,2)) | G36: ="2026-27" -> 2026-27
B37: 2 | C37: =IF(C6="","",C6) | D37: =IF(D6="","",D6) | E37: =IF(E6="","",E6) | F37: =IF(E37="","",ROUND(E37/3,2)) | G37: ="2026-27" -> 2026-27
B38: 3 | C38: =IF(C7="","",C7) | D38: =IF(D7="","",D7) | E38: =IF(E7="","",E7) | F38: =IF(E38="","",ROUND(E38/3,2)) | G38: ="2026-27" -> 2026-27
B39: 4 | C39: =IF(C8="","",C8) | D39: =IF(D8="","",D8) | E39: =IF(E8="","",E8) | F39: =IF(E39="","",ROUND(E39/3,2)) | G39: ="2026-27" -> 2026-27
B40: 5 | C40: =IF(C9="","",C9) | D40: =IF(D9="","",D9) | E40: =IF(E9="","",E9) | F40: =IF(E40="","",ROUND(E40/3,2)) | G40: ="2026-27" -> 2026-27
E41: Total Hours | F41: =SUM(F36:F40) -> 0 | G41: Final API 1.C
E42: API-1.A | F42: =ROUND(F41/10,2) -> 0 | G42: =MIN(F42,K35) -> 0
B44: API-1.A | C44: API-1.B | D44: API-1.C | E44: Final Score (Category 1)
B45: =H11 -> 0 | C45: =G31 -> 0 | D45: =G42 -> 0 | E45: =SUM(B45:D45) -> 0
A47: Category 2
...

Sheet 2027-28
A1: Category 1
A2: A | B2: Direct Teaching
B4: S. No. | C4: Course Name | D4: Course in | E4: Course Hours | F4: Total Course Hours | G4: API Score | H4: AY | J4: Max: | K4: =60 -> 60
B5: 1 | F5: =IF(OR(C5="",D5="",E5=""),"",IF(D5="Post Graduate",ROUND(E5*7/3,0),IF(D5="Under Graduate",ROUND(ROUND(E5*7/3,0)/2,1),""))) | G5: =IF(F5="","",ROUND(F5/10,2)) | H5: ="2027-28" -> 2027-28
B6: 2 | F6: =IF(OR(C6="",D6="",E6=""),"",IF(D6="Post Graduate",ROUND(E6*7/3,0),IF(D6="Under Graduate",ROUND(ROUND(E6*7/3,0)/2,1),""))) | G6: =IF(F6="","",ROUND(F6/10,2)) | H6: ="2027-28" -> 2027-28
B7: 3 | F7: =IF(OR(C7="",D7="",E7=""),"",IF(D7="Post Graduate",ROUND(E7*7/3,0),IF(D7="Under Graduate",ROUND(ROUND(E7*7/3,0)/2,1),""))) | G7: =IF(F7="","",ROUND(F7/10,2)) | H7: ="2027-28" -> 2027-28
B8: 4 | F8: =IF(OR(C8="",D8="",E8=""),"",IF(D8="Post Graduate",ROUND(E8*7/3,0),IF(D8="Under Graduate",ROUND(ROUND(E8*7/3,0)/2,1),""))) | G8: =IF(F8="","",ROUND(F8/10,2)) | H8: ="2027-28" -> 2027-28
B9: 5 | F9: =IF(OR(C9="",D9="",E9=""),"",IF(D9="Post Graduate",ROUND(E9*7/3,0),IF(D9="Under Graduate",ROUND(ROUND(E9*7/3,0)/2,1),""))) | G9: =IF(F9="","",ROUND(F9/10,2)) | H9: ="2027-28" -> 2027-28
D10: Total Hours | E10: =SUM(E5:E9) -> 0 | F10: =SUM(F5:F9) -> 0 | G10: =SUM(G5:G9) -> 0 | H10: Final API 1.A
D11: API 1.A | E11: =G10 -> 0 | H11: =MIN(E11,K4) -> 0
A13: B | B13: Examination Duties/Invigilation/Question Paper Setting / Evaluation
B15: S. No. | C15: Course | D15: Activity | E15: Hours | F15: Score | G15: AY | J15: Max: | K15: =20 -> 20
B16: Score/Point for Question Paper Setting | D16: (No. of courses taught) X 10 | E16: =COUNTA(C5:C9)*10 -> 0 | F16: =ROUND(E16/10,2) -> 0 | G16: ="2027-28" -> 2027-28
B17: Score/Point for Answer script Evalutation | D17: (No. of courses taught) X 20 | E17: =COUNTA(C5:C9)*20 -> 0 | F17: =ROUND(E17/10,2) -> 0 | G17: ="2027-28" -> 2027-28
B18: 1 | F18: =IF(OR(D18="",E18=""),"",ROUND(E18/10,2)) | G18: ="2027-28" -> 2027-28
B19: 2 | F19: =IF(OR(D19="",E19=""),"",ROUND(E19/10,2)) | G19: ="2027-28" -> 2027-28
B20: 3 | F20: =IF(OR(D20="",E20=""),"",ROUND(E20/10,2)) | G20: ="2027-28" -> 2027-28
B21: 4 | F21: =IF(OR(D21="",E21=""),"",ROUND(E21/10,2)) | G21: ="2027-28" -> 2027-28
B22: 5 | F22: =IF(OR(D22="",E22=""),"",ROUND(E22/10,2)) | G22: ="2027-28" -> 2027-28
B23: 6 | F23: =IF(OR(D23="",E23=""),"",ROUND(E23/10,2)) | G23: ="2027-28" -> 2027-28
B24: 7 | F24: =IF(OR(D24="",E24=""),"",ROUND(E24/10,2)) | G24: ="2027-28" -> 2027-28
B25: 8 | F25: =IF(OR(D25="",E25=""),"",ROUND(E25/10,2)) | G25: ="2027-28" -> 2027-28
B26: 9 | F26: =IF(OR(D26="",E26=""),"",ROUND(E26/10,2)) | G26: ="2027-28" -> 2027-28
B27: 10 | F27: =IF(OR(D27="",E27=""),"",ROUND(E27/10,2)) | G27: ="2027-28" -> 2027-28
B28: 11 | F28: =IF(OR(D28="",E28=""),"",ROUND(E28/10,2)) | G28: ="2027-28" -> 2027-28
B29: 12 | F29: =IF(OR(D29="",E29=""),"",ROUND(E29/10,2)) | G29: ="2027-28" -> 2027-28
D30: Total | E30: =SUM(E16:E29) -> 0 | F30: =SUM(F16:F29) -> 0 | G30: Final API 1.B
D31: API 1.B | E31: =F30 -> 0 | G31: =MIN(E31,K15) -> 0
A33: C | B33: Innovative Teaching
B35: S. No. | C35: Course Name | D35: Course in | E35: Course Hours | F35: Innovative Teaching Hours | G35: AY | J35: Max: | K35: =15 -> 15
B36: 1 | C36: =IF(C5="","",C5) | D36: =IF(D5="","",D5) | E36: =IF(E5="","",E5) | F36: =IF(E36="","",ROUND(E36/3,2)) | G36: ="2027-28" -> 2027-28
B37: 2 | C37: =IF(C6="","",C6) | D37: =IF(D6="","",D6) | E37: =IF(E6="","",E6) | F37: =IF(E37="","",ROUND(E37/3,2)) | G37: ="2027-28" -> 2027-28
B38: 3 | C38: =IF(C7="","",C7) | D38: =IF(D7="","",D7) | E38: =IF(E7="","",E7) | F38: =IF(E38="","",ROUND(E38/3,2)) | G38: ="2027-28" -> 2027-28
B39: 4 | C39: =IF(C8="","",C8) | D39: =IF(D8="","",D8) | E39: =IF(E8="","",E8) | F39: =IF(E39="","",ROUND(E39/3,2)) | G39: ="2027-28" -> 2027-28
B40: 5 | C40: =IF(C9="","",C9) | D40: =IF(D9="","",D9) | E40: =IF(E9="","",E9) | F40: =IF(E40="","",ROUND(E40/3,2)) | G40: ="2027-28" -> 2027-28
E41: Total Hours | F41: =SUM(F36:F40) -> 0 | G41: Final API 1.C
E42: API-1.A | F42: =ROUND(F41/10,2) -> 0 | G42: =MIN(F42,K35) -> 0
B44: API-1.A | C44: API-1.B | D44: API-1.C | E44: Final Score (Category 1)
B45: =H11 -> 0 | C45: =G31 -> 0 | D45: =G42 -> 0 | E45: =SUM(B45:D45) -> 0
A47: Category 2
...

Sheet 2028-29
A1: Category 1
A2: A | B2: Direct Teaching
B4: S. No. | C4: Course Name | D4: Course in | E4: Course Hours | F4: Total Course Hours | G4: API Score | H4: AY | J4: Max: | K4: =60 -> 60
B5: 1 | F5: =IF(OR(C5="",D5="",E5=""),"",IF(D5="Post Graduate",ROUND(E5*7/3,0),IF(D5="Under Graduate",ROUND(ROUND(E5*7/3,0)/2,1),""))) | G5: =IF(F5="","",ROUND(F5/10,2)) | H5: ="2028-29" -> 2028-29
B6: 2 | F6: =IF(OR(C6="",D6="",E6=""),"",IF(D6="Post Graduate",ROUND(E6*7/3,0),IF(D6="Under Graduate",ROUND(ROUND(E6*7/3,0)/2,1),""))) | G6: =IF(F6="","",ROUND(F6/10,2)) | H6: ="2028-29" -> 2028-29
B7: 3 | F7: =IF(OR(C7="",D7="",E7=""),"",IF(D7="Post Graduate",ROUND(E7*7/3,0),IF(D7="Under Graduate",ROUND(ROUND(E7*7/3,0)/2,1),""))) | G7: =IF(F7="","",ROUND(F7/10,2)) | H7: ="2028-29" -> 2028-29
B8: 4 | F8: =IF(OR(C8="",D8="",E8=""),"",IF(D8="Post Graduate",ROUND(E8*7/3,0),IF(D8="Under Graduate",ROUND(ROUND(E8*7/3,0)/2,1),""))) | G8: =IF(F8="","",ROUND(F8/10,2)) | H8: ="2028-29" -> 2028-29
B9: 5 | F9: =IF(OR(C9="",D9="",E9=""),"",IF(D9="Post Graduate",ROUND(E9*7/3,0),IF(D9="Under Graduate",ROUND(ROUND(E9*7/3,0)/2,1),""))) | G9: =IF(F9="","",ROUND(F9/10,2)) | H9: ="2028-29" -> 2028-29
D10: Total Hours | E10: =SUM(E5:E9) -> 0 | F10: =SUM(F5:F9) -> 0 | G10: =SUM(G5:G9) -> 0 | H10: Final API 1.A
D11: API 1.A | E11: =G10 -> 0 | H11: =MIN(E11,K4) -> 0
A13: B | B13: Examination Duties/Invigilation/Question Paper Setting / Evaluation
B15: S. No. | C15: Course | D15: Activity | E15: Hours | F15: Score | G15: AY | J15: Max: | K15: =20 -> 20
B16: Score/Point for Question Paper Setting | D16: (No. of courses taught) X 10 | E16: =COUNTA(C5:C9)*10 -> 0 | F16: =ROUND(E16/10,2) -> 0 | G16: ="2028-29" -> 2028-29
B17: Score/Point for Answer script Evalutation | D17: (No. of courses taught) X 20 | E17: =COUNTA(C5:C9)*20 -> 0 | F17: =ROUND(E17/10,2) -> 0 | G17: ="2028-29" -> 2028-29
B18: 1 | F18: =IF(OR(D18="",E18=""),"",ROUND(E18/10,2)) | G18: ="2028-29" -> 2028-29
B19: 2 | F19: =IF(OR(D19="",E19=""),"",ROUND(E19/10,2)) | G19: ="2028-29" -> 2028-29
B20: 3 | F20: =IF(OR(D20="",E20=""),"",ROUND(E20/10,2)) | G20: ="2028-29" -> 2028-29
B21: 4 | F21: =IF(OR(D21="",E21=""),"",ROUND(E21/10,2)) | G21: ="2028-29" -> 2028-29
B22: 5 | F22: =IF(OR(D22="",E22=""),"",ROUND(E22/10,2)) | G22: ="2028-29" -> 2028-29
B23: 6 | F23: =IF(OR(D23="",E23=""),"",ROUND(E23/10,2)) | G23: ="2028-29" -> 2028-29
B24: 7 | F24: =IF(OR(D24="",E24=""),"",ROUND(E24/10,2)) | G24: ="2028-29" -> 2028-29
B25: 8 | F25: =IF(OR(D25="",E25=""),"",ROUND(E25/10,2)) | G25: ="2028-29" -> 2028-29
B26: 9 | F26: =IF(OR(D26="",E26=""),"",ROUND(E26/10,2)) | G26: ="2028-29" -> 2028-29
B27: 10 | F27: =IF(OR(D27="",E27=""),"",ROUND(E27/10,2)) | G27: ="2028-29" -> 2028-29
B28: 11 | F28: =IF(OR(D28="",E28=""),"",ROUND(E28/10,2)) | G28: ="2028-29" -> 2028-29
B29: 12 | F29: =IF(OR(D29="",E29=""),"",ROUND(E29/10,2)) | G29: ="2028-29" -> 2028-29
D30: Total | E30: =SUM(E16:E29) -> 0 | F30: =SUM(F16:F29) -> 0 | G30: Final API 1.B
D31: API 1.B | E31: =F30 -> 0 | G31: =MIN(E31,K15) -> 0
A33: C | B33: Innovative Teaching
B35: S. No. | C35: Course Name | D35: Course in | E35: Course Hours | F35: Innovative Teaching Hours | G35: AY | J35: Max: | K35: =15 -> 15
B36: 1 | C36: =IF(C5="","",C5) | D36: =IF(D5="","",D5) | E36: =IF(E5="","",E5) | F36: =IF(E36="","",ROUND(E36/3,2)) | G36: ="2028-29" -> 2028-29
B37: 2 | C37: =IF(C6="","",C6) | D37: =IF(D6="","",D6) | E37: =IF(E6="","",E6) | F37: =IF(E37="","",ROUND(E37/3,2)) | G37: ="2028-29" -> 2028-29
B38: 3 | C38: =IF(C7="","",C7) | D38: =IF(D7="","",D7) | E38: =IF(E7="","",E7) | F38: =IF(E38="","",ROUND(E38/3,2)) | G38: ="2028-29" -> 2028-29
B39: 4 | C39: =IF(C8="","",C8) | D39: =IF(D8="","",D8) | E39: =IF(E8="","",E8) | F39: =IF(E39="","",ROUND(E39/3,2)) | G39: ="2028-29" -> 2028-29
B40: 5 | C40: =IF(C9="","",C9) | D40: =IF(D9="","",D9) | E40: =IF(E9="","",E9) | F40: =IF(E40="","",ROUND(E40/3,2)) | G40: ="2028-29" -> 2028-29
E41: Total Hours | F41: =SUM(F36:F40) -> 0 | G41: Final API 1.C
E42: API-1.A | F42: =ROUND(F41/10,2) -> 0 | G42: =MIN(F42,K35) -> 0
B44: API-1.A | C44: API-1.B | D44: API-1.C | E44: Final Score (Category 1)
B45: =H11 -> 0 | C45: =G31 -> 0 | D45: =G42 -> 0 | E45: =SUM(B45:D45) -> 0
A47: Category 2
...
